{
 "cells": [
  {
   "cell_type": "markdown",
   "id": "43500ded-06de-4a28-a53b-e86f8c5630e6",
   "metadata": {},
   "source": [
    "<span style=\"font-size: 2em;\">Gerekli kütüphanelerin indirilmesi</span>\n"
   ]
  },
  {
   "cell_type": "code",
   "execution_count": 1,
   "id": "1bb45ae6-ef25-463b-ad32-ac78e54b1411",
   "metadata": {
    "tags": []
   },
   "outputs": [],
   "source": [
    "#!pip install opencv-python"
   ]
  },
  {
   "cell_type": "code",
   "execution_count": 2,
   "id": "9aa7bdf2-cf10-4f69-92bb-28bca079226d",
   "metadata": {
    "tags": []
   },
   "outputs": [],
   "source": [
    "#!pip install deepface"
   ]
  },
  {
   "cell_type": "code",
   "execution_count": 3,
   "id": "3313d063-5504-4b44-a761-d0e232e55232",
   "metadata": {
    "tags": []
   },
   "outputs": [],
   "source": [
    "#!pip install pyttsx3"
   ]
  },
  {
   "cell_type": "code",
   "execution_count": 4,
   "id": "f5807fb1-569f-4631-82ab-95ae20d61de0",
   "metadata": {
    "tags": []
   },
   "outputs": [],
   "source": [
    "#!pip install SpeechRecognition"
   ]
  },
  {
   "cell_type": "code",
   "execution_count": 5,
   "id": "b5c95eea-1390-4534-ad27-343dc87520e1",
   "metadata": {
    "tags": []
   },
   "outputs": [],
   "source": [
    "#!pip install pygame"
   ]
  },
  {
   "cell_type": "code",
   "execution_count": 6,
   "id": "6343d739-7b04-469a-babe-dcb42d185aa5",
   "metadata": {
    "tags": []
   },
   "outputs": [],
   "source": [
    "#!pip install tensorflow"
   ]
  },
  {
   "cell_type": "code",
   "execution_count": 7,
   "id": "73fbacdf-60af-42ff-876b-03cc04ad04a8",
   "metadata": {
    "tags": []
   },
   "outputs": [],
   "source": [
    "#!pip install opencv-python --upgrade"
   ]
  },
  {
   "cell_type": "code",
   "execution_count": 8,
   "id": "16aa575e-7510-4414-89ce-c198483a2ff9",
   "metadata": {
    "tags": []
   },
   "outputs": [],
   "source": [
    "#!pip install deepface --upgrade"
   ]
  },
  {
   "cell_type": "code",
   "execution_count": 9,
   "id": "ab032c42-772b-417e-bb03-987fb1d5ef91",
   "metadata": {
    "tags": []
   },
   "outputs": [],
   "source": [
    "#!pip install PyAudio"
   ]
  },
  {
   "cell_type": "markdown",
   "id": "305b076e-519c-43e7-b166-0856fb0636e7",
   "metadata": {},
   "source": [
    "<span style=\"font-size: 2em;\">huggingface pipeline</span>"
   ]
  },
  {
   "cell_type": "code",
   "execution_count": 10,
   "id": "d11d33cf-2919-4685-94e0-67a622e32a91",
   "metadata": {},
   "outputs": [],
   "source": [
    "from transformers import pipeline"
   ]
  },
  {
   "cell_type": "code",
   "execution_count": 11,
   "id": "845b7e25-8d05-4c0a-aaae-ee4ebbc615c5",
   "metadata": {},
   "outputs": [],
   "source": [
    "def gptbot(user_input):  \n",
    "    generator = pipeline('text-generation', model='EleutherAI/gpt-neo-1.3B', device=0)\n",
    "    \n",
    "    print(\"Chatbot'a hoş geldiniz! Çıkmak için 'çık' yazabilirsiniz.\")\n",
    "    \n",
    "    while True:\n",
    "        # Kullanıcıdan soru alma\n",
    "        if user_input.lower() == \"çık\":\n",
    "            print(\"Chatbot: Görüşmek üzere!\")\n",
    "            break\n",
    "    \n",
    "        # Modelden cevap üretme\n",
    "        response = generator(\n",
    "            user_input,\n",
    "            max_length=50,\n",
    "            do_sample=True,\n",
    "            temperature=0.7,\n",
    "            top_k=50\n",
    "        )\n",
    "        \n",
    "        # Üretilen cevabı yazdırma\n",
    "        print(\"Chatbot:\", response[0]['generated_text'])\n",
    "        break"
   ]
  },
  {
   "cell_type": "markdown",
   "id": "0c81ea9d-c126-4601-9f8d-74cfa5531733",
   "metadata": {},
   "source": [
    "<span style=\"font-size: 2em;\">Chat-Bot fonksiyonları</span>"
   ]
  },
  {
   "cell_type": "code",
   "execution_count": 12,
   "id": "ca5acf0e-7590-4322-943e-2cb6cc440096",
   "metadata": {},
   "outputs": [],
   "source": [
    "#!pip install tf-keras"
   ]
  },
  {
   "cell_type": "code",
   "execution_count": 13,
   "id": "7264401b-83ba-4773-b9f9-ece369cb6195",
   "metadata": {
    "tags": []
   },
   "outputs": [
    {
     "name": "stdout",
     "output_type": "stream",
     "text": [
      "pygame 2.6.1 (SDL 2.28.4, Python 3.9.20)\n",
      "Hello from the pygame community. https://www.pygame.org/contribute.html\n"
     ]
    }
   ],
   "source": [
    "import speech_recognition as sr\n",
    "import pyttsx3\n",
    "import datetime\n",
    "import pygame\n",
    "import webbrowser\n",
    "import random\n",
    "import requests\n",
    "isim = 'yok'\n",
    "\n",
    "\n",
    "günler = {\n",
    "    \"Monday\": \"Pazartesi\",\n",
    "    \"Tuesday\": \"Salı\",\n",
    "    \"Wednesday\": \"Çarşamba\",\n",
    "    \"Thursday\": \"Perşembe\",\n",
    "    \"Friday\": \"Cuma\",\n",
    "    \"Saturday\": \"Cumartesi\",\n",
    "    \"Sunday\": \"Pazar\"\n",
    "}\n",
    "stop_bot = False\n",
    "api_key = \"8f39651fb818f04d1b08ef733c5b0711\"\n",
    "\n",
    "def speak(text):\n",
    "    engine = pyttsx3.init()\n",
    "    engine.setProperty('rate', 150)\n",
    "    engine.setProperty('voice', 'turkish')\n",
    "    engine.say(text)\n",
    "    engine.runAndWait()\n",
    "\n",
    "def play_number_game():\n",
    "    secret_number = random.randint(1, 100)\n",
    "    speak(\"Bir ile yüz arasında bir sayı tuttum. Tahmin et\")\n",
    "\n",
    "    while True:\n",
    "        query = listen()\n",
    "        if \"çıkış\" in query:\n",
    "            speak(f\"Oyun bitti. Doğru sayı {secret_number} idi.\")\n",
    "            break\n",
    "\n",
    "        if \"tahmin\" in query:\n",
    "            guess = int([int(s) for s in query.split() if s.isdigit()][0])\n",
    "            if guess == secret_number:\n",
    "                speak(\"Tebrikler! Doğru tahmin ettiniz.\")\n",
    "                break\n",
    "            elif guess < secret_number:\n",
    "                speak(\"Daha yüksek bir sayı söyleyin.\")\n",
    "            else:\n",
    "                speak(\"Daha düşük bir sayı söyleyin.\")\n",
    "        else:\n",
    "            speak(\"Lütfen bir sayı söyleyin veya çıkmak için 'çıkış' deyin.\")\n",
    "    \n",
    "def get_weather(api_key):\n",
    "    city_name = \"Kirsehir\"\n",
    "    base_url = \"http://api.openweathermap.org/data/2.5/weather\"\n",
    "    params = {\n",
    "        \"q\": city_name,\n",
    "        \"appid\": api_key,\n",
    "        \"units\": \"metric\",  # Metrik birimlerde hava durumu almak için\n",
    "        \"lang\": \"tr\"        # Türkçe dilinde hava durumu almak için\n",
    "    }\n",
    "\n",
    "    response = requests.get(base_url, params=params)\n",
    "\n",
    "    if response.status_code == 200:\n",
    "        data = response.json()\n",
    "        weather_desc = data[\"weather\"][0][\"description\"]\n",
    "        temp = data[\"main\"][\"temp\"]\n",
    "        result = f\"Kırşehir'de hava durumu: {weather_desc}. Sıcaklık: {temp}°C.\"\n",
    "        print(result)\n",
    "        return result\n",
    "    else:\n",
    "        return \"Hava durumu bilgisi alınamadı.\"\n",
    "\n",
    "def play_music():\n",
    "    pygame.init()\n",
    "    pygame.mixer.music.load('music1.mp3')\n",
    "    pygame.mixer.music.play()\n",
    "\n",
    "\n",
    "def listen():\n",
    "    recognizer = sr.Recognizer()\n",
    "    with sr.Microphone() as source:\n",
    "        recognizer.adjust_for_ambient_noise(source)\n",
    "        print(\"Sizi dinliyorum...\")\n",
    "        audio = recognizer.listen(source)\n",
    "        \n",
    "    try:\n",
    "        print(\"Ses algılanıyor, lütfen bekleyin...\")\n",
    "        text = recognizer.recognize_google(audio, language='tr-TR')\n",
    "        print(\"Ses algılandı:\", text)\n",
    "        return text.lower()\n",
    "    except sr.UnknownValueError:\n",
    "        return \"Anlaşılmadı\"\n",
    "    except sr.RequestError:\n",
    "        return \"Bağlantı hatası\"\n",
    "\n",
    "def chatbot_response(query):\n",
    "    global stop_bot\n",
    "    if \"gpt aktive et\" in query: #gpt bot calismasi\n",
    "        gptbot(\"query\")\n",
    "    elif \"nasılsın\" in query:\n",
    "        return \"İyiyim, teşekkür ederim. Siz nasılsınız?\"\n",
    "    elif \"bugün günlerden ne\" in query:\n",
    "        today_english = datetime.datetime.now().strftime(\"%A\")\n",
    "        today_turkish = günler.get(today_english, \"Bilinmiyor\")\n",
    "        print(today_turkish)\n",
    "        return f\"Bugün {today_turkish}.\"\n",
    "    elif \"yarın günlerden ne\" in query:\n",
    "        tomorrow = (datetime.datetime.now() + datetime.timedelta(days=1)).strftime(\"%A\")\n",
    "        tomorrow_turkish = günler.get(tomorrow, \"Bilinmiyor\")\n",
    "        return f\"Yarın {tomorrow_turkish}.\"\n",
    "    elif \"hava durumu\" in query:\n",
    "        return get_weather(api_key)\n",
    "    elif \"favori şarkımı çal\" in query:\n",
    "        play_music()\n",
    "        return \"Favori şarkınız çalınıyor.\"\n",
    "    elif \"benimle oyun oyna\" in query:\n",
    "        return play_number_game()\n",
    "    elif \"benim adım ne\" in query:\n",
    "        return f\"Senin adın {isim}.\"\n",
    "    elif \"durdur\" in query:\n",
    "        pygame.mixer.music.stop()\n",
    "        return \"Şarkı durduruldu.\"\n",
    "    elif \"kapat\" in query:\n",
    "        stop_bot = True\n",
    "        return \"Chatbot kapatılıyor.\"\n",
    "    else:\n",
    "        return \"Üzgünüm, bu konuda yardımcı olamıyorum.\""
   ]
  },
  {
   "cell_type": "markdown",
   "id": "f5f4d47d-491b-43ba-bf3b-c973455580d0",
   "metadata": {},
   "source": [
    "<span style=\"font-size: 2em;\">Yüz tanıma işlemleri</span>"
   ]
  },
  {
   "cell_type": "code",
   "execution_count": 14,
   "id": "a61af833-13cf-4f39-9a24-9103c3aeaf95",
   "metadata": {
    "tags": []
   },
   "outputs": [
    {
     "name": "stdout",
     "output_type": "stream",
     "text": [
      "WARNING:tensorflow:From C:\\Users\\Ufuk\\anaconda3\\envs\\environment2\\lib\\site-packages\\tf_keras\\src\\losses.py:2976: The name tf.losses.sparse_softmax_cross_entropy is deprecated. Please use tf.compat.v1.losses.sparse_softmax_cross_entropy instead.\n",
      "\n"
     ]
    },
    {
     "name": "stderr",
     "output_type": "stream",
     "text": [
      "Exception in thread Thread-4:\n",
      "Traceback (most recent call last):\n",
      "  File \"C:\\Users\\Ufuk\\anaconda3\\envs\\environment2\\lib\\threading.py\", line 980, in _bootstrap_inner\n",
      "    self.run()\n",
      "  File \"C:\\Users\\Ufuk\\anaconda3\\envs\\environment2\\lib\\site-packages\\ipykernel\\ipkernel.py\", line 766, in run_closure\n",
      "    _threading_Thread_run(self)\n",
      "  File \"C:\\Users\\Ufuk\\anaconda3\\envs\\environment2\\lib\\threading.py\", line 917, in run\n",
      "    self._target(*self._args, **self._kwargs)\n",
      "  File \"C:\\Users\\Ufuk\\AppData\\Local\\Temp\\ipykernel_21180\\4001011120.py\", line 29, in check_face1\n",
      "  File \"C:\\Users\\Ufuk\\anaconda3\\envs\\environment2\\lib\\site-packages\\deepface\\DeepFace.py\", line 150, in verify\n",
      "    return verification.verify(\n",
      "  File \"C:\\Users\\Ufuk\\anaconda3\\envs\\environment2\\lib\\site-packages\\deepface\\modules\\verification.py\", line 103, in verify\n",
      "    model: FacialRecognition = modeling.build_model(\n",
      "  File \"C:\\Users\\Ufuk\\anaconda3\\envs\\environment2\\lib\\site-packages\\deepface\\modules\\modeling.py\", line 96, in build_model\n",
      "    cached_models[task][model_name] = model()\n",
      "  File \"C:\\Users\\Ufuk\\anaconda3\\envs\\environment2\\lib\\site-packages\\deepface\\models\\facial_recognition\\VGGFace.py\", line 45, in __init__\n",
      "    self.model = load_model()\n",
      "  File \"C:\\Users\\Ufuk\\anaconda3\\envs\\environment2\\lib\\site-packages\\deepface\\models\\facial_recognition\\VGGFace.py\", line 158, in load_model\n",
      "    vgg_face_descriptor = Model(inputs=model.input, outputs=base_model_output)\n",
      "  File \"C:\\Users\\Ufuk\\anaconda3\\envs\\environment2\\lib\\site-packages\\keras\\src\\ops\\operation.py\", line 254, in input\n",
      "    return self._get_node_attribute_at_index(0, \"input_tensors\", \"input\")\n",
      "  File \"C:\\Users\\Ufuk\\anaconda3\\envs\\environment2\\lib\\site-packages\\keras\\src\\ops\\operation.py\", line 285, in _get_node_attribute_at_index\n",
      "    raise AttributeError(\n",
      "AttributeError: The layer sequential has never been called and thus has no defined input.\n",
      "Exception in thread Thread-5:\n",
      "Traceback (most recent call last):\n",
      "  File \"C:\\Users\\Ufuk\\anaconda3\\envs\\environment2\\lib\\threading.py\", line 980, in _bootstrap_inner\n",
      "    self.run()\n",
      "  File \"C:\\Users\\Ufuk\\anaconda3\\envs\\environment2\\lib\\site-packages\\ipykernel\\ipkernel.py\", line 766, in run_closure\n",
      "    _threading_Thread_run(self)\n",
      "  File \"C:\\Users\\Ufuk\\anaconda3\\envs\\environment2\\lib\\threading.py\", line 917, in run\n",
      "    self._target(*self._args, **self._kwargs)\n",
      "  File \"C:\\Users\\Ufuk\\AppData\\Local\\Temp\\ipykernel_21180\\4001011120.py\", line 40, in check_face2\n",
      "  File \"C:\\Users\\Ufuk\\anaconda3\\envs\\environment2\\lib\\site-packages\\deepface\\DeepFace.py\", line 150, in verify\n",
      "    return verification.verify(\n",
      "  File \"C:\\Users\\Ufuk\\anaconda3\\envs\\environment2\\lib\\site-packages\\deepface\\modules\\verification.py\", line 103, in verify\n",
      "    model: FacialRecognition = modeling.build_model(\n",
      "  File \"C:\\Users\\Ufuk\\anaconda3\\envs\\environment2\\lib\\site-packages\\deepface\\modules\\modeling.py\", line 96, in build_model\n",
      "    cached_models[task][model_name] = model()\n",
      "  File \"C:\\Users\\Ufuk\\anaconda3\\envs\\environment2\\lib\\site-packages\\deepface\\models\\facial_recognition\\VGGFace.py\", line 45, in __init__\n",
      "    self.model = load_model()\n",
      "  File \"C:\\Users\\Ufuk\\anaconda3\\envs\\environment2\\lib\\site-packages\\deepface\\models\\facial_recognition\\VGGFace.py\", line 158, in load_model\n",
      "    vgg_face_descriptor = Model(inputs=model.input, outputs=base_model_output)\n",
      "  File \"C:\\Users\\Ufuk\\anaconda3\\envs\\environment2\\lib\\site-packages\\keras\\src\\ops\\operation.py\", line 254, in input\n",
      "    return self._get_node_attribute_at_index(0, \"input_tensors\", \"input\")\n",
      "  File \"C:\\Users\\Ufuk\\anaconda3\\envs\\environment2\\lib\\site-packages\\keras\\src\\ops\\operation.py\", line 285, in _get_node_attribute_at_index\n",
      "    raise AttributeError(\n",
      "AttributeError: The layer sequential has never been called and thus has no defined input.\n",
      "Exception in thread Thread-7:\n",
      "Traceback (most recent call last):\n",
      "  File \"C:\\Users\\Ufuk\\anaconda3\\envs\\environment2\\lib\\threading.py\", line 980, in _bootstrap_inner\n",
      "    self.run()\n",
      "  File \"C:\\Users\\Ufuk\\anaconda3\\envs\\environment2\\lib\\site-packages\\ipykernel\\ipkernel.py\", line 766, in run_closure\n",
      "    _threading_Thread_run(self)\n",
      "  File \"C:\\Users\\Ufuk\\anaconda3\\envs\\environment2\\lib\\threading.py\", line 917, in run\n",
      "    self._target(*self._args, **self._kwargs)\n",
      "  File \"C:\\Users\\Ufuk\\AppData\\Local\\Temp\\ipykernel_21180\\4001011120.py\", line 40, in check_face2\n",
      "  File \"C:\\Users\\Ufuk\\anaconda3\\envs\\environment2\\lib\\site-packages\\deepface\\DeepFace.py\", line 150, in verify\n",
      "    return verification.verify(\n",
      "  File \"C:\\Users\\Ufuk\\anaconda3\\envs\\environment2\\lib\\site-packages\\deepface\\modules\\verification.py\", line 103, in verify\n",
      "    model: FacialRecognition = modeling.build_model(\n",
      "  File \"C:\\Users\\Ufuk\\anaconda3\\envs\\environment2\\lib\\site-packages\\deepface\\modules\\modeling.py\", line 96, in build_model\n",
      "    cached_models[task][model_name] = model()\n",
      "  File \"C:\\Users\\Ufuk\\anaconda3\\envs\\environment2\\lib\\site-packages\\deepface\\models\\facial_recognition\\VGGFace.py\", line 45, in __init__\n",
      "    self.model = load_model()\n",
      "  File \"C:\\Users\\Ufuk\\anaconda3\\envs\\environment2\\lib\\site-packages\\deepface\\models\\facial_recognition\\VGGFace.py\", line 158, in load_model\n",
      "    vgg_face_descriptor = Model(inputs=model.input, outputs=base_model_output)\n",
      "  File \"C:\\Users\\Ufuk\\anaconda3\\envs\\environment2\\lib\\site-packages\\keras\\src\\ops\\operation.py\", line 254, in input\n",
      "    return self._get_node_attribute_at_index(0, \"input_tensors\", \"input\")\n",
      "  File \"C:\\Users\\Ufuk\\anaconda3\\envs\\environment2\\lib\\site-packages\\keras\\src\\ops\\operation.py\", line 285, in _get_node_attribute_at_index\n",
      "    raise AttributeError(\n",
      "AttributeError: The layer sequential has never been called and thus has no defined input.\n",
      "Exception in thread Thread-6:\n",
      "Traceback (most recent call last):\n",
      "  File \"C:\\Users\\Ufuk\\anaconda3\\envs\\environment2\\lib\\threading.py\", line 980, in _bootstrap_inner\n",
      "    self.run()\n",
      "  File \"C:\\Users\\Ufuk\\anaconda3\\envs\\environment2\\lib\\site-packages\\ipykernel\\ipkernel.py\", line 766, in run_closure\n",
      "    _threading_Thread_run(self)\n",
      "  File \"C:\\Users\\Ufuk\\anaconda3\\envs\\environment2\\lib\\threading.py\", line 917, in run\n",
      "    self._target(*self._args, **self._kwargs)\n",
      "  File \"C:\\Users\\Ufuk\\AppData\\Local\\Temp\\ipykernel_21180\\4001011120.py\", line 29, in check_face1\n",
      "  File \"C:\\Users\\Ufuk\\anaconda3\\envs\\environment2\\lib\\site-packages\\deepface\\DeepFace.py\", line 150, in verify\n",
      "    return verification.verify(\n",
      "  File \"C:\\Users\\Ufuk\\anaconda3\\envs\\environment2\\lib\\site-packages\\deepface\\modules\\verification.py\", line 103, in verify\n",
      "    model: FacialRecognition = modeling.build_model(\n",
      "  File \"C:\\Users\\Ufuk\\anaconda3\\envs\\environment2\\lib\\site-packages\\deepface\\modules\\modeling.py\", line 96, in build_model\n",
      "    cached_models[task][model_name] = model()\n",
      "  File \"C:\\Users\\Ufuk\\anaconda3\\envs\\environment2\\lib\\site-packages\\deepface\\models\\facial_recognition\\VGGFace.py\", line 45, in __init__\n",
      "    self.model = load_model()\n",
      "  File \"C:\\Users\\Ufuk\\anaconda3\\envs\\environment2\\lib\\site-packages\\deepface\\models\\facial_recognition\\VGGFace.py\", line 158, in load_model\n",
      "    vgg_face_descriptor = Model(inputs=model.input, outputs=base_model_output)\n",
      "  File \"C:\\Users\\Ufuk\\anaconda3\\envs\\environment2\\lib\\site-packages\\keras\\src\\ops\\operation.py\", line 254, in input\n",
      "    return self._get_node_attribute_at_index(0, \"input_tensors\", \"input\")\n",
      "  File \"C:\\Users\\Ufuk\\anaconda3\\envs\\environment2\\lib\\site-packages\\keras\\src\\ops\\operation.py\", line 285, in _get_node_attribute_at_index\n",
      "    raise AttributeError(\n",
      "AttributeError: The layer sequential has never been called and thus has no defined input.\n",
      "Exception in thread Thread-9:\n",
      "Traceback (most recent call last):\n",
      "  File \"C:\\Users\\Ufuk\\anaconda3\\envs\\environment2\\lib\\threading.py\", line 980, in _bootstrap_inner\n",
      "    self.run()\n",
      "  File \"C:\\Users\\Ufuk\\anaconda3\\envs\\environment2\\lib\\site-packages\\ipykernel\\ipkernel.py\", line 766, in run_closure\n",
      "    _threading_Thread_run(self)\n",
      "  File \"C:\\Users\\Ufuk\\anaconda3\\envs\\environment2\\lib\\threading.py\", line 917, in run\n",
      "    self._target(*self._args, **self._kwargs)\n",
      "  File \"C:\\Users\\Ufuk\\AppData\\Local\\Temp\\ipykernel_21180\\4001011120.py\", line 40, in check_face2\n",
      "Exception in thread Thread-8:\n",
      "Traceback (most recent call last):\n",
      "  File \"C:\\Users\\Ufuk\\anaconda3\\envs\\environment2\\lib\\threading.py\", line 980, in _bootstrap_inner\n",
      "  File \"C:\\Users\\Ufuk\\anaconda3\\envs\\environment2\\lib\\site-packages\\deepface\\DeepFace.py\", line 150, in verify\n",
      "    return verification.verify(\n",
      "  File \"C:\\Users\\Ufuk\\anaconda3\\envs\\environment2\\lib\\site-packages\\deepface\\modules\\verification.py\", line 103, in verify\n",
      "    self.run()\n",
      "  File \"C:\\Users\\Ufuk\\anaconda3\\envs\\environment2\\lib\\site-packages\\ipykernel\\ipkernel.py\", line 766, in run_closure\n",
      "    model: FacialRecognition = modeling.build_model(\n",
      "  File \"C:\\Users\\Ufuk\\anaconda3\\envs\\environment2\\lib\\site-packages\\deepface\\modules\\modeling.py\", line 96, in build_model\n",
      "    cached_models[task][model_name] = model()\n",
      "  File \"C:\\Users\\Ufuk\\anaconda3\\envs\\environment2\\lib\\site-packages\\deepface\\models\\facial_recognition\\VGGFace.py\", line 45, in __init__\n",
      "    _threading_Thread_run(self)\n",
      "  File \"C:\\Users\\Ufuk\\anaconda3\\envs\\environment2\\lib\\threading.py\", line 917, in run\n",
      "    self.model = load_model()\n",
      "  File \"C:\\Users\\Ufuk\\anaconda3\\envs\\environment2\\lib\\site-packages\\deepface\\models\\facial_recognition\\VGGFace.py\", line 158, in load_model\n",
      "    self._target(*self._args, **self._kwargs)\n",
      "  File \"C:\\Users\\Ufuk\\AppData\\Local\\Temp\\ipykernel_21180\\4001011120.py\", line 29, in check_face1\n",
      "  File \"C:\\Users\\Ufuk\\anaconda3\\envs\\environment2\\lib\\site-packages\\deepface\\DeepFace.py\", line 150, in verify\n",
      "    return verification.verify(\n",
      "  File \"C:\\Users\\Ufuk\\anaconda3\\envs\\environment2\\lib\\site-packages\\deepface\\modules\\verification.py\", line 103, in verify\n",
      "    vgg_face_descriptor = Model(inputs=model.input, outputs=base_model_output)\n",
      "  File \"C:\\Users\\Ufuk\\anaconda3\\envs\\environment2\\lib\\site-packages\\keras\\src\\ops\\operation.py\", line 254, in input\n",
      "    model: FacialRecognition = modeling.build_model(\n",
      "  File \"C:\\Users\\Ufuk\\anaconda3\\envs\\environment2\\lib\\site-packages\\deepface\\modules\\modeling.py\", line 96, in build_model\n",
      "    return self._get_node_attribute_at_index(0, \"input_tensors\", \"input\")\n",
      "  File \"C:\\Users\\Ufuk\\anaconda3\\envs\\environment2\\lib\\site-packages\\keras\\src\\ops\\operation.py\", line 285, in _get_node_attribute_at_index\n",
      "    cached_models[task][model_name] = model()\n",
      "  File \"C:\\Users\\Ufuk\\anaconda3\\envs\\environment2\\lib\\site-packages\\deepface\\models\\facial_recognition\\VGGFace.py\", line 45, in __init__\n",
      "    raise AttributeError(\n",
      "AttributeError: The layer sequential has never been called and thus has no defined input.\n",
      "    self.model = load_model()\n",
      "  File \"C:\\Users\\Ufuk\\anaconda3\\envs\\environment2\\lib\\site-packages\\deepface\\models\\facial_recognition\\VGGFace.py\", line 158, in load_model\n",
      "    vgg_face_descriptor = Model(inputs=model.input, outputs=base_model_output)\n",
      "  File \"C:\\Users\\Ufuk\\anaconda3\\envs\\environment2\\lib\\site-packages\\keras\\src\\ops\\operation.py\", line 254, in input\n",
      "    return self._get_node_attribute_at_index(0, \"input_tensors\", \"input\")\n",
      "  File \"C:\\Users\\Ufuk\\anaconda3\\envs\\environment2\\lib\\site-packages\\keras\\src\\ops\\operation.py\", line 285, in _get_node_attribute_at_index\n",
      "    raise AttributeError(\n",
      "AttributeError: The layer sequential has never been called and thus has no defined input.\n",
      "Exception in thread Thread-11:\n",
      "Traceback (most recent call last):\n",
      "  File \"C:\\Users\\Ufuk\\anaconda3\\envs\\environment2\\lib\\threading.py\", line 980, in _bootstrap_inner\n",
      "    self.run()\n",
      "  File \"C:\\Users\\Ufuk\\anaconda3\\envs\\environment2\\lib\\site-packages\\ipykernel\\ipkernel.py\", line 766, in run_closure\n",
      "    _threading_Thread_run(self)\n",
      "  File \"C:\\Users\\Ufuk\\anaconda3\\envs\\environment2\\lib\\threading.py\", line 917, in run\n",
      "    self._target(*self._args, **self._kwargs)\n",
      "  File \"C:\\Users\\Ufuk\\AppData\\Local\\Temp\\ipykernel_21180\\4001011120.py\", line 40, in check_face2\n",
      "  File \"C:\\Users\\Ufuk\\anaconda3\\envs\\environment2\\lib\\site-packages\\deepface\\DeepFace.py\", line 150, in verify\n",
      "    return verification.verify(\n",
      "  File \"C:\\Users\\Ufuk\\anaconda3\\envs\\environment2\\lib\\site-packages\\deepface\\modules\\verification.py\", line 103, in verify\n",
      "    model: FacialRecognition = modeling.build_model(\n",
      "  File \"C:\\Users\\Ufuk\\anaconda3\\envs\\environment2\\lib\\site-packages\\deepface\\modules\\modeling.py\", line 96, in build_model\n",
      "    cached_models[task][model_name] = model()\n",
      "  File \"C:\\Users\\Ufuk\\anaconda3\\envs\\environment2\\lib\\site-packages\\deepface\\models\\facial_recognition\\VGGFace.py\", line 45, in __init__\n",
      "    self.model = load_model()\n",
      "  File \"C:\\Users\\Ufuk\\anaconda3\\envs\\environment2\\lib\\site-packages\\deepface\\models\\facial_recognition\\VGGFace.py\", line 158, in load_model\n",
      "    vgg_face_descriptor = Model(inputs=model.input, outputs=base_model_output)\n",
      "  File \"C:\\Users\\Ufuk\\anaconda3\\envs\\environment2\\lib\\site-packages\\keras\\src\\ops\\operation.py\", line 254, in input\n",
      "    return self._get_node_attribute_at_index(0, \"input_tensors\", \"input\")\n",
      "  File \"C:\\Users\\Ufuk\\anaconda3\\envs\\environment2\\lib\\site-packages\\keras\\src\\ops\\operation.py\", line 285, in _get_node_attribute_at_index\n",
      "    raise AttributeError(\n",
      "AttributeError: The layer sequential has never been called and thus has no defined input.\n",
      "Exception in thread Thread-17:\n",
      "Traceback (most recent call last):\n",
      "  File \"C:\\Users\\Ufuk\\anaconda3\\envs\\environment2\\lib\\threading.py\", line 980, in _bootstrap_inner\n",
      "    self.run()\n",
      "  File \"C:\\Users\\Ufuk\\anaconda3\\envs\\environment2\\lib\\site-packages\\ipykernel\\ipkernel.py\", line 766, in run_closure\n",
      "    _threading_Thread_run(self)\n",
      "  File \"C:\\Users\\Ufuk\\anaconda3\\envs\\environment2\\lib\\threading.py\", line 917, in run\n",
      "    self._target(*self._args, **self._kwargs)\n",
      "  File \"C:\\Users\\Ufuk\\AppData\\Local\\Temp\\ipykernel_21180\\4001011120.py\", line 40, in check_face2\n",
      "  File \"C:\\Users\\Ufuk\\anaconda3\\envs\\environment2\\lib\\site-packages\\deepface\\DeepFace.py\", line 150, in verify\n",
      "    return verification.verify(\n",
      "  File \"C:\\Users\\Ufuk\\anaconda3\\envs\\environment2\\lib\\site-packages\\deepface\\modules\\verification.py\", line 103, in verify\n",
      "    model: FacialRecognition = modeling.build_model(\n",
      "  File \"C:\\Users\\Ufuk\\anaconda3\\envs\\environment2\\lib\\site-packages\\deepface\\modules\\modeling.py\", line 96, in build_model\n",
      "    cached_models[task][model_name] = model()\n",
      "  File \"C:\\Users\\Ufuk\\anaconda3\\envs\\environment2\\lib\\site-packages\\deepface\\models\\facial_recognition\\VGGFace.py\", line 45, in __init__\n",
      "    self.model = load_model()\n",
      "  File \"C:\\Users\\Ufuk\\anaconda3\\envs\\environment2\\lib\\site-packages\\deepface\\models\\facial_recognition\\VGGFace.py\", line 143, in load_model\n",
      "    model.load_weights(output)\n",
      "  File \"C:\\Users\\Ufuk\\anaconda3\\envs\\environment2\\lib\\site-packages\\keras\\src\\utils\\traceback_utils.py\", line 122, in error_handler\n",
      "Exception in thread Thread-13:\n",
      "Traceback (most recent call last):\n",
      "  File \"C:\\Users\\Ufuk\\anaconda3\\envs\\environment2\\lib\\threading.py\", line 980, in _bootstrap_inner\n",
      "    raise e.with_traceback(filtered_tb) from None\n",
      "  File \"C:\\Users\\Ufuk\\anaconda3\\envs\\environment2\\lib\\site-packages\\tensorflow\\python\\framework\\constant_op.py\", line 96, in convert_to_eager_tensor\n",
      "    self.run()\n",
      "  File \"C:\\Users\\Ufuk\\anaconda3\\envs\\environment2\\lib\\site-packages\\ipykernel\\ipkernel.py\", line 766, in run_closure\n",
      "    _threading_Thread_run(self)\n",
      "  File \"C:\\Users\\Ufuk\\anaconda3\\envs\\environment2\\lib\\threading.py\", line 917, in run\n",
      "    value = value.copy()\n",
      "numpy._core._exceptions._ArrayMemoryError: Unable to allocate 392. MiB for an array with shape (7, 7, 512, 4096) and data type float32\n",
      "    self._target(*self._args, **self._kwargs)\n",
      "  File \"C:\\Users\\Ufuk\\AppData\\Local\\Temp\\ipykernel_21180\\4001011120.py\", line 40, in check_face2\n",
      "  File \"C:\\Users\\Ufuk\\anaconda3\\envs\\environment2\\lib\\site-packages\\deepface\\DeepFace.py\", line 150, in verify\n",
      "    return verification.verify(\n",
      "  File \"C:\\Users\\Ufuk\\anaconda3\\envs\\environment2\\lib\\site-packages\\deepface\\modules\\verification.py\", line 103, in verify\n",
      "    model: FacialRecognition = modeling.build_model(\n",
      "  File \"C:\\Users\\Ufuk\\anaconda3\\envs\\environment2\\lib\\site-packages\\deepface\\modules\\modeling.py\", line 96, in build_model\n",
      "    cached_models[task][model_name] = model()\n",
      "  File \"C:\\Users\\Ufuk\\anaconda3\\envs\\environment2\\lib\\site-packages\\deepface\\models\\facial_recognition\\VGGFace.py\", line 45, in __init__\n",
      "    self.model = load_model()\n",
      "  File \"C:\\Users\\Ufuk\\anaconda3\\envs\\environment2\\lib\\site-packages\\deepface\\models\\facial_recognition\\VGGFace.py\", line 143, in load_model\n",
      "    model.load_weights(output)\n",
      "  File \"C:\\Users\\Ufuk\\anaconda3\\envs\\environment2\\lib\\site-packages\\keras\\src\\utils\\traceback_utils.py\", line 122, in error_handler\n",
      "    raise e.with_traceback(filtered_tb) from None\n",
      "  File \"h5py\\\\_objects.pyx\", line 54, in h5py._objects.with_phil.wrapper\n",
      "  File \"h5py\\\\_objects.pyx\", line 55, in h5py._objects.with_phil.wrapper\n",
      "  File \"C:\\Users\\Ufuk\\anaconda3\\envs\\environment2\\lib\\site-packages\\h5py\\_hl\\dataset.py\", line 1085, in __array__\n",
      "    arr = numpy.zeros(self.shape, dtype=self.dtype if dtype is None else dtype)\n",
      "numpy._core._exceptions._ArrayMemoryError: Unable to allocate 392. MiB for an array with shape (7, 7, 512, 4096) and data type float32\n",
      "Exception in thread Thread-16:\n",
      "Traceback (most recent call last):\n",
      "  File \"C:\\Users\\Ufuk\\anaconda3\\envs\\environment2\\lib\\threading.py\", line 980, in _bootstrap_inner\n",
      "Exception in thread Thread-10:\n",
      "Traceback (most recent call last):\n",
      "  File \"C:\\Users\\Ufuk\\anaconda3\\envs\\environment2\\lib\\threading.py\", line 980, in _bootstrap_inner\n",
      "    self.run()\n",
      "  File \"C:\\Users\\Ufuk\\anaconda3\\envs\\environment2\\lib\\site-packages\\ipykernel\\ipkernel.py\", line 766, in run_closure\n",
      "    self.run()\n",
      "  File \"C:\\Users\\Ufuk\\anaconda3\\envs\\environment2\\lib\\site-packages\\ipykernel\\ipkernel.py\", line 766, in run_closure\n",
      "    _threading_Thread_run(self)\n",
      "  File \"C:\\Users\\Ufuk\\anaconda3\\envs\\environment2\\lib\\threading.py\", line 917, in run\n",
      "    _threading_Thread_run(self)\n",
      "  File \"C:\\Users\\Ufuk\\anaconda3\\envs\\environment2\\lib\\threading.py\", line 917, in run\n",
      "    self._target(*self._args, **self._kwargs)\n",
      "  File \"C:\\Users\\Ufuk\\AppData\\Local\\Temp\\ipykernel_21180\\4001011120.py\", line 29, in check_face1\n",
      "    self._target(*self._args, **self._kwargs)\n",
      "  File \"C:\\Users\\Ufuk\\AppData\\Local\\Temp\\ipykernel_21180\\4001011120.py\", line 29, in check_face1\n",
      "  File \"C:\\Users\\Ufuk\\anaconda3\\envs\\environment2\\lib\\site-packages\\deepface\\DeepFace.py\", line 150, in verify\n",
      "  File \"C:\\Users\\Ufuk\\anaconda3\\envs\\environment2\\lib\\site-packages\\deepface\\DeepFace.py\", line 150, in verify\n",
      "    return verification.verify(\n",
      "  File \"C:\\Users\\Ufuk\\anaconda3\\envs\\environment2\\lib\\site-packages\\deepface\\modules\\verification.py\", line 103, in verify\n",
      "    model: FacialRecognition = modeling.build_model(\n",
      "  File \"C:\\Users\\Ufuk\\anaconda3\\envs\\environment2\\lib\\site-packages\\deepface\\modules\\modeling.py\", line 96, in build_model\n",
      "    return verification.verify(\n",
      "  File \"C:\\Users\\Ufuk\\anaconda3\\envs\\environment2\\lib\\site-packages\\deepface\\modules\\verification.py\", line 103, in verify\n",
      "    cached_models[task][model_name] = model()\n",
      "  File \"C:\\Users\\Ufuk\\anaconda3\\envs\\environment2\\lib\\site-packages\\deepface\\models\\facial_recognition\\VGGFace.py\", line 45, in __init__\n",
      "    model: FacialRecognition = modeling.build_model(\n",
      "  File \"C:\\Users\\Ufuk\\anaconda3\\envs\\environment2\\lib\\site-packages\\deepface\\modules\\modeling.py\", line 96, in build_model\n",
      "    cached_models[task][model_name] = model()\n",
      "  File \"C:\\Users\\Ufuk\\anaconda3\\envs\\environment2\\lib\\site-packages\\deepface\\models\\facial_recognition\\VGGFace.py\", line 45, in __init__\n",
      "    self.model = load_model()\n",
      "  File \"C:\\Users\\Ufuk\\anaconda3\\envs\\environment2\\lib\\site-packages\\deepface\\models\\facial_recognition\\VGGFace.py\", line 143, in load_model\n",
      "    self.model = load_model()\n",
      "  File \"C:\\Users\\Ufuk\\anaconda3\\envs\\environment2\\lib\\site-packages\\deepface\\models\\facial_recognition\\VGGFace.py\", line 143, in load_model\n",
      "    model.load_weights(output)\n",
      "  File \"C:\\Users\\Ufuk\\anaconda3\\envs\\environment2\\lib\\site-packages\\keras\\src\\utils\\traceback_utils.py\", line 122, in error_handler\n",
      "    model.load_weights(output)\n",
      "  File \"C:\\Users\\Ufuk\\anaconda3\\envs\\environment2\\lib\\site-packages\\keras\\src\\utils\\traceback_utils.py\", line 122, in error_handler\n",
      "    raise e.with_traceback(filtered_tb) from None\n",
      "  File \"h5py\\\\_objects.pyx\", line 54, in h5py._objects.with_phil.wrapper\n",
      "    raise e.with_traceback(filtered_tb) from None\n",
      "  File \"h5py\\\\_objects.pyx\", line 54, in h5py._objects.with_phil.wrapper\n",
      "  File \"h5py\\\\_objects.pyx\", line 55, in h5py._objects.with_phil.wrapper\n",
      "  File \"h5py\\\\_objects.pyx\", line 55, in h5py._objects.with_phil.wrapper\n",
      "  File \"C:\\Users\\Ufuk\\anaconda3\\envs\\environment2\\lib\\site-packages\\h5py\\_hl\\dataset.py\", line 1085, in __array__\n",
      "  File \"C:\\Users\\Ufuk\\anaconda3\\envs\\environment2\\lib\\site-packages\\h5py\\_hl\\dataset.py\", line 1085, in __array__\n",
      "    arr = numpy.zeros(self.shape, dtype=self.dtype if dtype is None else dtype)\n",
      "numpy._core._exceptions._ArrayMemoryError: Unable to allocate 392. MiB for an array with shape (7, 7, 512, 4096) and data type float32\n",
      "    arr = numpy.zeros(self.shape, dtype=self.dtype if dtype is None else dtype)\n",
      "numpy._core._exceptions._ArrayMemoryError: Unable to allocate 392. MiB for an array with shape (7, 7, 512, 4096) and data type float32\n",
      "Exception in thread Exception in thread Thread-15:\n",
      "Traceback (most recent call last):\n",
      "  File \"C:\\Users\\Ufuk\\anaconda3\\envs\\environment2\\lib\\threading.py\", line 980, in _bootstrap_inner\n",
      "Thread-12:\n",
      "Traceback (most recent call last):\n",
      "  File \"C:\\Users\\Ufuk\\anaconda3\\envs\\environment2\\lib\\threading.py\", line 980, in _bootstrap_inner\n",
      "    self.run()\n",
      "  File \"C:\\Users\\Ufuk\\anaconda3\\envs\\environment2\\lib\\site-packages\\ipykernel\\ipkernel.py\", line 766, in run_closure\n",
      "    self.run()\n",
      "  File \"C:\\Users\\Ufuk\\anaconda3\\envs\\environment2\\lib\\site-packages\\ipykernel\\ipkernel.py\", line 766, in run_closure\n",
      "    _threading_Thread_run(self)\n",
      "  File \"C:\\Users\\Ufuk\\anaconda3\\envs\\environment2\\lib\\threading.py\", line 917, in run\n",
      "    self._target(*self._args, **self._kwargs)\n",
      "  File \"C:\\Users\\Ufuk\\AppData\\Local\\Temp\\ipykernel_21180\\4001011120.py\", line 40, in check_face2\n",
      "    _threading_Thread_run(self)\n",
      "  File \"C:\\Users\\Ufuk\\anaconda3\\envs\\environment2\\lib\\threading.py\", line 917, in run\n",
      "    self._target(*self._args, **self._kwargs)\n",
      "  File \"C:\\Users\\Ufuk\\AppData\\Local\\Temp\\ipykernel_21180\\4001011120.py\", line 29, in check_face1\n",
      "  File \"C:\\Users\\Ufuk\\anaconda3\\envs\\environment2\\lib\\site-packages\\deepface\\DeepFace.py\", line 150, in verify\n",
      "  File \"C:\\Users\\Ufuk\\anaconda3\\envs\\environment2\\lib\\site-packages\\deepface\\DeepFace.py\", line 150, in verify\n",
      "    return verification.verify(\n",
      "  File \"C:\\Users\\Ufuk\\anaconda3\\envs\\environment2\\lib\\site-packages\\deepface\\modules\\verification.py\", line 103, in verify\n",
      "    return verification.verify(\n",
      "  File \"C:\\Users\\Ufuk\\anaconda3\\envs\\environment2\\lib\\site-packages\\deepface\\modules\\verification.py\", line 103, in verify\n",
      "    model: FacialRecognition = modeling.build_model(\n",
      "  File \"C:\\Users\\Ufuk\\anaconda3\\envs\\environment2\\lib\\site-packages\\deepface\\modules\\modeling.py\", line 96, in build_model\n",
      "    model: FacialRecognition = modeling.build_model(\n",
      "  File \"C:\\Users\\Ufuk\\anaconda3\\envs\\environment2\\lib\\site-packages\\deepface\\modules\\modeling.py\", line 96, in build_model\n",
      "    cached_models[task][model_name] = model()\n",
      "  File \"C:\\Users\\Ufuk\\anaconda3\\envs\\environment2\\lib\\site-packages\\deepface\\models\\facial_recognition\\VGGFace.py\", line 45, in __init__\n",
      "    cached_models[task][model_name] = model()\n",
      "  File \"C:\\Users\\Ufuk\\anaconda3\\envs\\environment2\\lib\\site-packages\\deepface\\models\\facial_recognition\\VGGFace.py\", line 45, in __init__\n",
      "    self.model = load_model()\n",
      "  File \"C:\\Users\\Ufuk\\anaconda3\\envs\\environment2\\lib\\site-packages\\deepface\\models\\facial_recognition\\VGGFace.py\", line 143, in load_model\n",
      "    self.model = load_model()\n",
      "  File \"C:\\Users\\Ufuk\\anaconda3\\envs\\environment2\\lib\\site-packages\\deepface\\models\\facial_recognition\\VGGFace.py\", line 143, in load_model\n",
      "    model.load_weights(output)\n",
      "  File \"C:\\Users\\Ufuk\\anaconda3\\envs\\environment2\\lib\\site-packages\\keras\\src\\utils\\traceback_utils.py\", line 122, in error_handler\n",
      "    model.load_weights(output)\n",
      "  File \"C:\\Users\\Ufuk\\anaconda3\\envs\\environment2\\lib\\site-packages\\keras\\src\\utils\\traceback_utils.py\", line 122, in error_handler\n",
      "    raise e.with_traceback(filtered_tb) from None\n",
      "  File \"h5py\\\\_objects.pyx\", line 54, in h5py._objects.with_phil.wrapper\n",
      "    raise e.with_traceback(filtered_tb) from None\n",
      "  File \"h5py\\\\_objects.pyx\", line 54, in h5py._objects.with_phil.wrapper\n",
      "  File \"h5py\\\\_objects.pyx\", line 55, in h5py._objects.with_phil.wrapper\n",
      "  File \"h5py\\\\_objects.pyx\", line 55, in h5py._objects.with_phil.wrapper\n",
      "  File \"C:\\Users\\Ufuk\\anaconda3\\envs\\environment2\\lib\\site-packages\\h5py\\_hl\\dataset.py\", line 1085, in __array__\n",
      "  File \"C:\\Users\\Ufuk\\anaconda3\\envs\\environment2\\lib\\site-packages\\h5py\\_hl\\dataset.py\", line 1085, in __array__\n",
      "    arr = numpy.zeros(self.shape, dtype=self.dtype if dtype is None else dtype)\n",
      "numpy._core._exceptions._ArrayMemoryError: Unable to allocate 392. MiB for an array with shape (7, 7, 512, 4096) and data type float32\n",
      "    arr = numpy.zeros(self.shape, dtype=self.dtype if dtype is None else dtype)\n",
      "numpy._core._exceptions._ArrayMemoryError: Unable to allocate 392. MiB for an array with shape (7, 7, 512, 4096) and data type float32\n",
      "Exception in thread Thread-14:\n",
      "Traceback (most recent call last):\n",
      "  File \"C:\\Users\\Ufuk\\anaconda3\\envs\\environment2\\lib\\threading.py\", line 980, in _bootstrap_inner\n",
      "    self.run()\n",
      "  File \"C:\\Users\\Ufuk\\anaconda3\\envs\\environment2\\lib\\site-packages\\ipykernel\\ipkernel.py\", line 766, in run_closure\n",
      "    _threading_Thread_run(self)\n",
      "  File \"C:\\Users\\Ufuk\\anaconda3\\envs\\environment2\\lib\\threading.py\", line 917, in run\n",
      "    self._target(*self._args, **self._kwargs)\n",
      "  File \"C:\\Users\\Ufuk\\AppData\\Local\\Temp\\ipykernel_21180\\4001011120.py\", line 29, in check_face1\n",
      "  File \"C:\\Users\\Ufuk\\anaconda3\\envs\\environment2\\lib\\site-packages\\deepface\\DeepFace.py\", line 150, in verify\n",
      "    return verification.verify(\n",
      "  File \"C:\\Users\\Ufuk\\anaconda3\\envs\\environment2\\lib\\site-packages\\deepface\\modules\\verification.py\", line 103, in verify\n",
      "    model: FacialRecognition = modeling.build_model(\n",
      "  File \"C:\\Users\\Ufuk\\anaconda3\\envs\\environment2\\lib\\site-packages\\deepface\\modules\\modeling.py\", line 96, in build_model\n",
      "    cached_models[task][model_name] = model()\n",
      "  File \"C:\\Users\\Ufuk\\anaconda3\\envs\\environment2\\lib\\site-packages\\deepface\\models\\facial_recognition\\VGGFace.py\", line 45, in __init__\n",
      "    self.model = load_model()\n",
      "  File \"C:\\Users\\Ufuk\\anaconda3\\envs\\environment2\\lib\\site-packages\\deepface\\models\\facial_recognition\\VGGFace.py\", line 143, in load_model\n",
      "    model.load_weights(output)\n",
      "  File \"C:\\Users\\Ufuk\\anaconda3\\envs\\environment2\\lib\\site-packages\\keras\\src\\utils\\traceback_utils.py\", line 122, in error_handler\n",
      "    raise e.with_traceback(filtered_tb) from None\n",
      "  File \"h5py\\\\_objects.pyx\", line 54, in h5py._objects.with_phil.wrapper\n",
      "  File \"h5py\\\\_objects.pyx\", line 55, in h5py._objects.with_phil.wrapper\n",
      "  File \"C:\\Users\\Ufuk\\anaconda3\\envs\\environment2\\lib\\site-packages\\h5py\\_hl\\dataset.py\", line 1085, in __array__\n",
      "    arr = numpy.zeros(self.shape, dtype=self.dtype if dtype is None else dtype)\n",
      "numpy._core._exceptions._ArrayMemoryError: Unable to allocate 392. MiB for an array with shape (7, 7, 512, 4096) and data type float32\n",
      "Exception in thread Thread-18:\n",
      "Traceback (most recent call last):\n",
      "  File \"C:\\Users\\Ufuk\\anaconda3\\envs\\environment2\\lib\\threading.py\", line 980, in _bootstrap_inner\n",
      "    self.run()\n",
      "  File \"C:\\Users\\Ufuk\\anaconda3\\envs\\environment2\\lib\\site-packages\\ipykernel\\ipkernel.py\", line 766, in run_closure\n",
      "    _threading_Thread_run(self)\n",
      "  File \"C:\\Users\\Ufuk\\anaconda3\\envs\\environment2\\lib\\threading.py\", line 917, in run\n",
      "    self._target(*self._args, **self._kwargs)\n",
      "  File \"C:\\Users\\Ufuk\\AppData\\Local\\Temp\\ipykernel_21180\\4001011120.py\", line 29, in check_face1\n",
      "  File \"C:\\Users\\Ufuk\\anaconda3\\envs\\environment2\\lib\\site-packages\\deepface\\DeepFace.py\", line 150, in verify\n",
      "    return verification.verify(\n",
      "  File \"C:\\Users\\Ufuk\\anaconda3\\envs\\environment2\\lib\\site-packages\\deepface\\modules\\verification.py\", line 103, in verify\n",
      "    model: FacialRecognition = modeling.build_model(\n",
      "  File \"C:\\Users\\Ufuk\\anaconda3\\envs\\environment2\\lib\\site-packages\\deepface\\modules\\modeling.py\", line 96, in build_model\n",
      "    cached_models[task][model_name] = model()\n",
      "  File \"C:\\Users\\Ufuk\\anaconda3\\envs\\environment2\\lib\\site-packages\\deepface\\models\\facial_recognition\\VGGFace.py\", line 45, in __init__\n",
      "    self.model = load_model()\n",
      "  File \"C:\\Users\\Ufuk\\anaconda3\\envs\\environment2\\lib\\site-packages\\deepface\\models\\facial_recognition\\VGGFace.py\", line 143, in load_model\n",
      "    model.load_weights(output)\n",
      "  File \"C:\\Users\\Ufuk\\anaconda3\\envs\\environment2\\lib\\site-packages\\keras\\src\\utils\\traceback_utils.py\", line 122, in error_handler\n",
      "    raise e.with_traceback(filtered_tb) from None\n",
      "  File \"h5py\\\\_objects.pyx\", line 54, in h5py._objects.with_phil.wrapper\n",
      "  File \"h5py\\\\_objects.pyx\", line 55, in h5py._objects.with_phil.wrapper\n",
      "  File \"C:\\Users\\Ufuk\\anaconda3\\envs\\environment2\\lib\\site-packages\\h5py\\_hl\\dataset.py\", line 1085, in __array__\n",
      "    arr = numpy.zeros(self.shape, dtype=self.dtype if dtype is None else dtype)\n",
      "numpy._core._exceptions._ArrayMemoryError: Unable to allocate 392. MiB for an array with shape (7, 7, 512, 4096) and data type float32\n",
      "Exception in thread Thread-19:\n",
      "Traceback (most recent call last):\n",
      "  File \"C:\\Users\\Ufuk\\anaconda3\\envs\\environment2\\lib\\threading.py\", line 980, in _bootstrap_inner\n",
      "    self.run()\n",
      "  File \"C:\\Users\\Ufuk\\anaconda3\\envs\\environment2\\lib\\site-packages\\ipykernel\\ipkernel.py\", line 766, in run_closure\n",
      "    _threading_Thread_run(self)\n",
      "  File \"C:\\Users\\Ufuk\\anaconda3\\envs\\environment2\\lib\\threading.py\", line 917, in run\n",
      "    self._target(*self._args, **self._kwargs)\n",
      "  File \"C:\\Users\\Ufuk\\AppData\\Local\\Temp\\ipykernel_21180\\4001011120.py\", line 40, in check_face2\n",
      "  File \"C:\\Users\\Ufuk\\anaconda3\\envs\\environment2\\lib\\site-packages\\deepface\\DeepFace.py\", line 150, in verify\n",
      "    return verification.verify(\n",
      "  File \"C:\\Users\\Ufuk\\anaconda3\\envs\\environment2\\lib\\site-packages\\deepface\\modules\\verification.py\", line 103, in verify\n",
      "    model: FacialRecognition = modeling.build_model(\n",
      "  File \"C:\\Users\\Ufuk\\anaconda3\\envs\\environment2\\lib\\site-packages\\deepface\\modules\\modeling.py\", line 96, in build_model\n",
      "    cached_models[task][model_name] = model()\n",
      "  File \"C:\\Users\\Ufuk\\anaconda3\\envs\\environment2\\lib\\site-packages\\deepface\\models\\facial_recognition\\VGGFace.py\", line 45, in __init__\n",
      "    self.model = load_model()\n",
      "  File \"C:\\Users\\Ufuk\\anaconda3\\envs\\environment2\\lib\\site-packages\\deepface\\models\\facial_recognition\\VGGFace.py\", line 143, in load_model\n",
      "    model.load_weights(output)\n",
      "  File \"C:\\Users\\Ufuk\\anaconda3\\envs\\environment2\\lib\\site-packages\\keras\\src\\utils\\traceback_utils.py\", line 122, in error_handler\n",
      "    raise e.with_traceback(filtered_tb) from None\n",
      "  File \"h5py\\\\_objects.pyx\", line 54, in h5py._objects.with_phil.wrapper\n",
      "  File \"h5py\\\\_objects.pyx\", line 55, in h5py._objects.with_phil.wrapper\n",
      "  File \"C:\\Users\\Ufuk\\anaconda3\\envs\\environment2\\lib\\site-packages\\h5py\\_hl\\dataset.py\", line 1085, in __array__\n",
      "    arr = numpy.zeros(self.shape, dtype=self.dtype if dtype is None else dtype)\n",
      "numpy._core._exceptions._ArrayMemoryError: Unable to allocate 392. MiB for an array with shape (7, 7, 512, 4096) and data type float32\n",
      "Exception in thread Thread-23:\n",
      "Traceback (most recent call last):\n",
      "  File \"C:\\Users\\Ufuk\\anaconda3\\envs\\environment2\\lib\\threading.py\", line 980, in _bootstrap_inner\n",
      "    self.run()\n",
      "  File \"C:\\Users\\Ufuk\\anaconda3\\envs\\environment2\\lib\\site-packages\\ipykernel\\ipkernel.py\", line 766, in run_closure\n",
      "    _threading_Thread_run(self)\n",
      "  File \"C:\\Users\\Ufuk\\anaconda3\\envs\\environment2\\lib\\threading.py\", line 917, in run\n",
      "    self._target(*self._args, **self._kwargs)\n",
      "  File \"C:\\Users\\Ufuk\\AppData\\Local\\Temp\\ipykernel_21180\\4001011120.py\", line 40, in check_face2\n",
      "Exception in thread Thread-21:\n",
      "Traceback (most recent call last):\n",
      "  File \"C:\\Users\\Ufuk\\anaconda3\\envs\\environment2\\lib\\threading.py\", line 980, in _bootstrap_inner\n",
      "    self.run()\n",
      "  File \"C:\\Users\\Ufuk\\anaconda3\\envs\\environment2\\lib\\site-packages\\ipykernel\\ipkernel.py\", line 766, in run_closure\n",
      "Exception in thread Thread-20:\n",
      "Traceback (most recent call last):\n",
      "  File \"C:\\Users\\Ufuk\\anaconda3\\envs\\environment2\\lib\\threading.py\", line 980, in _bootstrap_inner\n",
      "  File \"C:\\Users\\Ufuk\\anaconda3\\envs\\environment2\\lib\\site-packages\\deepface\\DeepFace.py\", line 150, in verify\n",
      "    _threading_Thread_run(self)\n",
      "  File \"C:\\Users\\Ufuk\\anaconda3\\envs\\environment2\\lib\\threading.py\", line 917, in run\n",
      "    return verification.verify(\n",
      "  File \"C:\\Users\\Ufuk\\anaconda3\\envs\\environment2\\lib\\site-packages\\deepface\\modules\\verification.py\", line 103, in verify\n",
      "    self.run()\n",
      "  File \"C:\\Users\\Ufuk\\anaconda3\\envs\\environment2\\lib\\site-packages\\ipykernel\\ipkernel.py\", line 766, in run_closure\n",
      "    model: FacialRecognition = modeling.build_model(\n",
      "  File \"C:\\Users\\Ufuk\\anaconda3\\envs\\environment2\\lib\\site-packages\\deepface\\modules\\modeling.py\", line 96, in build_model\n",
      "    self._target(*self._args, **self._kwargs)\n",
      "  File \"C:\\Users\\Ufuk\\AppData\\Local\\Temp\\ipykernel_21180\\4001011120.py\", line 40, in check_face2\n",
      "    _threading_Thread_run(self)\n",
      "  File \"C:\\Users\\Ufuk\\anaconda3\\envs\\environment2\\lib\\threading.py\", line 917, in run\n",
      "    cached_models[task][model_name] = model()\n",
      "  File \"C:\\Users\\Ufuk\\anaconda3\\envs\\environment2\\lib\\site-packages\\deepface\\models\\facial_recognition\\VGGFace.py\", line 45, in __init__\n",
      "    self._target(*self._args, **self._kwargs)\n",
      "  File \"C:\\Users\\Ufuk\\AppData\\Local\\Temp\\ipykernel_21180\\4001011120.py\", line 29, in check_face1\n",
      "  File \"C:\\Users\\Ufuk\\anaconda3\\envs\\environment2\\lib\\site-packages\\deepface\\DeepFace.py\", line 150, in verify\n",
      "    self.model = load_model()\n",
      "  File \"C:\\Users\\Ufuk\\anaconda3\\envs\\environment2\\lib\\site-packages\\deepface\\models\\facial_recognition\\VGGFace.py\", line 143, in load_model\n",
      "    return verification.verify(\n",
      "  File \"C:\\Users\\Ufuk\\anaconda3\\envs\\environment2\\lib\\site-packages\\deepface\\modules\\verification.py\", line 103, in verify\n",
      "    model.load_weights(output)\n",
      "  File \"C:\\Users\\Ufuk\\anaconda3\\envs\\environment2\\lib\\site-packages\\keras\\src\\utils\\traceback_utils.py\", line 122, in error_handler\n",
      "  File \"C:\\Users\\Ufuk\\anaconda3\\envs\\environment2\\lib\\site-packages\\deepface\\DeepFace.py\", line 150, in verify\n",
      "    model: FacialRecognition = modeling.build_model(\n",
      "  File \"C:\\Users\\Ufuk\\anaconda3\\envs\\environment2\\lib\\site-packages\\deepface\\modules\\modeling.py\", line 96, in build_model\n",
      "    raise e.with_traceback(filtered_tb) from None\n",
      "  File \"h5py\\\\_objects.pyx\", line 54, in h5py._objects.with_phil.wrapper\n",
      "    return verification.verify(\n",
      "  File \"C:\\Users\\Ufuk\\anaconda3\\envs\\environment2\\lib\\site-packages\\deepface\\modules\\verification.py\", line 103, in verify\n",
      "    cached_models[task][model_name] = model()\n",
      "  File \"C:\\Users\\Ufuk\\anaconda3\\envs\\environment2\\lib\\site-packages\\deepface\\models\\facial_recognition\\VGGFace.py\", line 45, in __init__\n",
      "    model: FacialRecognition = modeling.build_model(\n",
      "  File \"C:\\Users\\Ufuk\\anaconda3\\envs\\environment2\\lib\\site-packages\\deepface\\modules\\modeling.py\", line 96, in build_model\n",
      "  File \"h5py\\\\_objects.pyx\", line 55, in h5py._objects.with_phil.wrapper\n",
      "    self.model = load_model()\n",
      "  File \"C:\\Users\\Ufuk\\anaconda3\\envs\\environment2\\lib\\site-packages\\deepface\\models\\facial_recognition\\VGGFace.py\", line 143, in load_model\n",
      "Exception in thread Thread-22:\n",
      "Traceback (most recent call last):\n",
      "  File \"C:\\Users\\Ufuk\\anaconda3\\envs\\environment2\\lib\\threading.py\", line 980, in _bootstrap_inner\n",
      "    cached_models[task][model_name] = model()\n",
      "  File \"C:\\Users\\Ufuk\\anaconda3\\envs\\environment2\\lib\\site-packages\\deepface\\models\\facial_recognition\\VGGFace.py\", line 45, in __init__\n",
      "    model.load_weights(output)\n",
      "  File \"C:\\Users\\Ufuk\\anaconda3\\envs\\environment2\\lib\\site-packages\\keras\\src\\utils\\traceback_utils.py\", line 122, in error_handler\n",
      "    self.run()\n",
      "  File \"C:\\Users\\Ufuk\\anaconda3\\envs\\environment2\\lib\\site-packages\\ipykernel\\ipkernel.py\", line 766, in run_closure\n",
      "  File \"C:\\Users\\Ufuk\\anaconda3\\envs\\environment2\\lib\\site-packages\\h5py\\_hl\\dataset.py\", line 1085, in __array__\n",
      "    self.model = load_model()\n",
      "  File \"C:\\Users\\Ufuk\\anaconda3\\envs\\environment2\\lib\\site-packages\\deepface\\models\\facial_recognition\\VGGFace.py\", line 143, in load_model\n",
      "    raise e.with_traceback(filtered_tb) from None\n",
      "  File \"h5py\\\\_objects.pyx\", line 54, in h5py._objects.with_phil.wrapper\n",
      "    arr = numpy.zeros(self.shape, dtype=self.dtype if dtype is None else dtype)\n",
      "numpy._core._exceptions._ArrayMemoryError: Unable to allocate 9.00 MiB for an array with shape (3, 3, 512, 512) and data type float32\n",
      "    _threading_Thread_run(self)\n",
      "  File \"C:\\Users\\Ufuk\\anaconda3\\envs\\environment2\\lib\\threading.py\", line 917, in run\n",
      "    model.load_weights(output)\n",
      "  File \"C:\\Users\\Ufuk\\anaconda3\\envs\\environment2\\lib\\site-packages\\keras\\src\\utils\\traceback_utils.py\", line 122, in error_handler\n",
      "    self._target(*self._args, **self._kwargs)\n",
      "  File \"C:\\Users\\Ufuk\\AppData\\Local\\Temp\\ipykernel_21180\\4001011120.py\", line 29, in check_face1\n",
      "    raise e.with_traceback(filtered_tb) from None\n",
      "  File \"h5py\\\\_objects.pyx\", line 54, in h5py._objects.with_phil.wrapper\n",
      "  File \"h5py\\\\_objects.pyx\", line 55, in h5py._objects.with_phil.wrapper\n",
      "  File \"C:\\Users\\Ufuk\\anaconda3\\envs\\environment2\\lib\\site-packages\\deepface\\DeepFace.py\", line 150, in verify\n",
      "  File \"C:\\Users\\Ufuk\\anaconda3\\envs\\environment2\\lib\\site-packages\\h5py\\_hl\\dataset.py\", line 1085, in __array__\n",
      "  File \"h5py\\\\_objects.pyx\", line 55, in h5py._objects.with_phil.wrapper\n",
      "    return verification.verify(\n",
      "  File \"C:\\Users\\Ufuk\\anaconda3\\envs\\environment2\\lib\\site-packages\\deepface\\modules\\verification.py\", line 103, in verify\n",
      "    model: FacialRecognition = modeling.build_model(\n",
      "  File \"C:\\Users\\Ufuk\\anaconda3\\envs\\environment2\\lib\\site-packages\\deepface\\modules\\modeling.py\", line 96, in build_model\n",
      "    arr = numpy.zeros(self.shape, dtype=self.dtype if dtype is None else dtype)\n",
      "numpy._core._exceptions._ArrayMemoryError: Unable to allocate 9.00 MiB for an array with shape (3, 3, 512, 512) and data type float32\n",
      "  File \"C:\\Users\\Ufuk\\anaconda3\\envs\\environment2\\lib\\site-packages\\h5py\\_hl\\dataset.py\", line 1085, in __array__\n",
      "    cached_models[task][model_name] = model()\n",
      "  File \"C:\\Users\\Ufuk\\anaconda3\\envs\\environment2\\lib\\site-packages\\deepface\\models\\facial_recognition\\VGGFace.py\", line 45, in __init__\n",
      "    arr = numpy.zeros(self.shape, dtype=self.dtype if dtype is None else dtype)\n",
      "numpy._core._exceptions._ArrayMemoryError: Unable to allocate 9.00 MiB for an array with shape (3, 3, 512, 512) and data type float32\n",
      "    self.model = load_model()\n",
      "  File \"C:\\Users\\Ufuk\\anaconda3\\envs\\environment2\\lib\\site-packages\\deepface\\models\\facial_recognition\\VGGFace.py\", line 143, in load_model\n",
      "    model.load_weights(output)\n",
      "  File \"C:\\Users\\Ufuk\\anaconda3\\envs\\environment2\\lib\\site-packages\\keras\\src\\utils\\traceback_utils.py\", line 122, in error_handler\n",
      "    raise e.with_traceback(filtered_tb) from None\n",
      "  File \"h5py\\\\_objects.pyx\", line 54, in h5py._objects.with_phil.wrapper\n",
      "  File \"h5py\\\\_objects.pyx\", line 55, in h5py._objects.with_phil.wrapper\n",
      "  File \"C:\\Users\\Ufuk\\anaconda3\\envs\\environment2\\lib\\site-packages\\h5py\\_hl\\dataset.py\", line 1085, in __array__\n",
      "    arr = numpy.zeros(self.shape, dtype=self.dtype if dtype is None else dtype)\n",
      "numpy._core._exceptions._ArrayMemoryError: Unable to allocate 4.50 MiB for an array with shape (3, 3, 256, 512) and data type float32\n"
     ]
    }
   ],
   "source": [
    "import threading\n",
    "import cv2\n",
    "from deepface import DeepFace\n",
    "import time\n",
    "import pyttsx3\n",
    "import speech_recognition as sr\n",
    "\n",
    "stop_threads = threading.Event()\n",
    "engine = pyttsx3.init()\n",
    "is_spoken = False\n",
    "stop_bot = False\n",
    "bot_responded = False\n",
    "cap = cv2.VideoCapture(0, cv2.CAP_DSHOW)\n",
    "cap.set(cv2.CAP_PROP_FRAME_WIDTH, 640)\n",
    "cap.set(cv2.CAP_PROP_FRAME_HEIGHT, 480)\n",
    "\n",
    "counter = 0\n",
    "\n",
    "reference_img1 = cv2.imread(\"ufukcandemirsoy.jpeg\")\n",
    "reference_img2 = cv2.imread(\"second.jpg\")\n",
    "\n",
    "face_match1 = False\n",
    "face_match2 = False\n",
    "\n",
    "\n",
    "def check_face1(frame):\n",
    "    global face_match1\n",
    "    try:\n",
    "        if DeepFace.verify(frame, reference_img1.copy())['verified']:\n",
    "            face_match1 = True\n",
    "        else:\n",
    "            face_match1 = False\n",
    "            \n",
    "    except ValueError:\n",
    "        face_match1 = False\n",
    "\n",
    "def check_face2(frame):\n",
    "    global face_match2\n",
    "    try:\n",
    "        if DeepFace.verify(frame, reference_img2.copy())['verified']:\n",
    "            face_match2 = True\n",
    "            \n",
    "        else:\n",
    "            face_match2 = False\n",
    "            \n",
    "    except ValueError:\n",
    "        face_match2 = False\n",
    "\n",
    "def chatbot_thread_func():\n",
    "    global stop_bot\n",
    "    while not stop_bot:\n",
    "        query = listen()\n",
    "        response = chatbot_response(query)\n",
    "        speak(response)\n",
    "        if stop_bot:\n",
    "            break\n",
    "\n",
    "chatbot_thread = threading.Thread(target=chatbot_thread_func)\n",
    "\n",
    "while True:\n",
    "    bot_responded = False\n",
    "    if stop_bot:\n",
    "        stop_bot = False\n",
    "        chatbot_thread.join()\n",
    "        \n",
    "    ret, frame = cap.read()\n",
    "\n",
    "    if ret:\n",
    "        if counter % 30 == 0:\n",
    "            if not stop_threads.is_set():\n",
    "                try:\n",
    "                    threading.Thread(target=check_face1, args=(frame.copy(),)).start()\n",
    "                    threading.Thread(target=check_face2, args=(frame.copy(),)).start()\n",
    "                except ValueError:\n",
    "                    pass\n",
    "        counter += 1\n",
    "\n",
    "        if face_match1:\n",
    "            cv2.putText(frame, \"Ufuk!\", (20, 450), cv2.FONT_HERSHEY_SIMPLEX, 2, (0, 255, 0), 1)\n",
    "            isim = 'Ufuk'\n",
    "            #print(isim)\n",
    "            if not chatbot_thread.is_alive():\n",
    "                chatbot_thread = threading.Thread(target=chatbot_thread_func)\n",
    "                chatbot_thread.start()\n",
    "            \n",
    "        else:\n",
    "            stop_threads.clear()\n",
    "            cv2.putText(frame, \"eslesme yok 1\", (20, 450), cv2.FONT_HERSHEY_SIMPLEX, 2, (0, 0, 255), 1)\n",
    "            \n",
    "        if face_match2:\n",
    "            cv2.putText(frame, \"Second!\", (20, 400), cv2.FONT_HERSHEY_SIMPLEX, 2, (0, 255, 0), 1)\n",
    "            isim = 'Second'\n",
    "            if not chatbot_thread.is_alive():\n",
    "                chatbot_thread = threading.Thread(target=chatbot_thread_func)\n",
    "                chatbot_thread.start()\n",
    "            \n",
    "        else:\n",
    "            cv2.putText(frame, \"eslesme yok 2\", (20, 400), cv2.FONT_HERSHEY_SIMPLEX, 2, (0, 0, 255), 1)\n",
    "        \n",
    "        cv2.imshow('video', frame)\n",
    "\n",
    "    key = cv2.waitKey(1)\n",
    "    if key == ord('q') or stop_bot:\n",
    "        break\n",
    "\n",
    "cv2.destroyAllWindows()\n",
    "cap.release()\n"
   ]
  },
  {
   "cell_type": "code",
   "execution_count": 15,
   "id": "e92dc9c2-91a8-4e2d-af6c-383bbb76560c",
   "metadata": {},
   "outputs": [],
   "source": [
    "#!pip install pyowm"
   ]
  },
  {
   "cell_type": "code",
   "execution_count": null,
   "id": "ecb98dd8-48ee-4047-a86d-fb5958861162",
   "metadata": {},
   "outputs": [],
   "source": []
  },
  {
   "cell_type": "code",
   "execution_count": null,
   "id": "24675232-5702-4eea-a031-5bfeb84663b1",
   "metadata": {},
   "outputs": [],
   "source": []
  }
 ],
 "metadata": {
  "kernelspec": {
   "display_name": "Python 3 (ipykernel)",
   "language": "python",
   "name": "python3"
  },
  "language_info": {
   "codemirror_mode": {
    "name": "ipython",
    "version": 3
   },
   "file_extension": ".py",
   "mimetype": "text/x-python",
   "name": "python",
   "nbconvert_exporter": "python",
   "pygments_lexer": "ipython3",
   "version": "3.9.20"
  }
 },
 "nbformat": 4,
 "nbformat_minor": 5
}
